Workbook
Name 覆盖场景: [1]枚举值sheet!$D$1:$D$50

Sheet 总表
A1: 2026年4月人力资源数据分析表（总表）
A2: 部门 | B2: 人员分类 | C2: 4月人数 | D2: 占比 | E2: 与上月同期比 | F2: 大专以上人员 | G2: 大专 | H2: 电工证 | I2: 登高证 | J2: 焊工证 | K2: 安全员(通管局） | L2: 安全员（建设厅） | M2: 一级建造师 | N2: 二级建造师
A3: 合计 | B3: 管理人员 | C3: =C7+C11+C15+C19+C23+C27+C31+C35 -> 3 | D3: =C3/$C$6 -> #DIV/0! | E3: =(C3-174)/174 -> -0.98275862 | F3: =F7+F11+F15+F19+F23+F27+F31+F35 -> 4 | G3: =G7+G11+G15+G19+G23+G27+G31+G35 -> 1 | H3: =H7+H11+H15+H19+H23+H27+H31+H35 -> 0 | I3: =I7+I11+I15+I19+I23+I27+I31+I35 -> 0 | J3: =J7+J11+J15+J19+J23+J27+J31+J35 -> 0 | K3: =K7+K11+K15+K19+K23+K27+K31+K35 -> 0 | L3: =L7+L11+L15+L19+L23+L27+L31+L35 -> 0 | M3: =M7+M11+M15+M19+M23+M27+M31+M35 -> 0 | N3: =N7+N11+N15+N19+N23+N27+N31+N35 -> 0
B4: 商务人员 | C4: =C8+C12+C16+C20+C24+C28+C32+C36 -> 0 | D4: =C4/$C$6 -> #DIV/0! | E4: =(C4-9)/9 -> -1 | F4: =F8+F12+F16+F20+F24+F28+F32+F36 -> 0 | G4: =G8+G12+G16+G20+G24+G28+G32+G36 -> 0 | H4: =H8+H12+H16+H20+H24+H28+H32+H36 -> 0 | I4: =I8+I12+I16+I20+I24+I28+I32+I36 -> 0 | J4: =J8+J12+J16+J20+J24+J28+J32+J36 -> 0 | K4: =K8+K12+K16+K20+K24+K28+K32+K36 -> 0 | L4: =L8+L12+L16+L20+L24+L28+L32+L36 -> 0 | M4: =M8+M12+M16+M20+M24+M28+M32+M36 -> 0 | N4: =N8+N12+N16+N20+N24+N28+N32+N36 -> 0
B5: 生产人员 | C5: =C9+C13+C17+C21+C25+C29+C33+C37 -> -3 | D5: =C5/$C$6 -> #DIV/0! | E5: =(C5-2450)/2450 -> -1.0012245 | F5: =F9+F13+F17+F21+F25+F29+F33+F37 -> 0 | G5: =G9+G13+G17+G21+G25+G29+G33+G37 -> 0 | H5: =H9+H13+H17+H21+H25+H29+H33+H37 -> 0 | I5: =I9+I13+I17+I21+I25+I29+I33+I37 -> 0 | J5: =J9+J13+J17+J21+J25+J29+J33+J37 -> 0 | K5: =K9+K13+K17+K21+K25+K29+K33+K37 -> 0 | L5: =L9+L13+L17+L21+L25+L29+L33+L37 -> 0 | M5: =M9+M13+M17+M21+M25+M29+M33+M37 -> 0 | N5: =N9+N13+N17+N21+N25+N29+N33+N37 -> 0
B6: 小计 | C6: =SUM(C3:C5) -> 0 | D6: / | E6: =(C6-2633)/2633 -> -1 | F6: =SUM(F3:F5) -> 4 | G6: =SUM(G3:G5) -> 1 | H6: =SUM(H3:H5) -> 0 | I6: =SUM(I3:I5) -> 0 | J6: =SUM(J3:J5) -> 0 | K6: =SUM(K3:K5) -> 0 | L6: =SUM(L3:L5) -> 0 | M6: =SUM(M3:M5) -> 0 | N6: =SUM(N3:N5) -> 0
A7: 总部 | B7: 管理人员 | C7: =COUNTIFS(花名册!B:B,$A$7,花名册!J:J,B7)+COUNTIFS(花名册!B:B,$A$7,花名册!J:J,"注册人员")+3 -> 3 | D7: =C7/$C$10 -> 1 | E7: =(C7-57)/57 -> -0.94736842 | F7: =COUNTIFS(花名册!B:B,$A$7,花名册!N:N,"博士",花名册!B:B,$A$7,花名册!J:J,B7)+COUNTIFS(花名册!B:B,$A$7,花名册!N:N,"硕士",花名册!B:B,$A$7,花名册!J:J,B7)+COUNTIFS(花名册!B:B,$A$7,花名册!N:N,"本科",花名册!B:B,$A$7,花名册!J:J,B7)+4 -> 4 | G7: =COUNTIFS(花名册!B:B,$A$7,花名册!N:N,"大专",花名册!J:J,B7)+1 -> 1 | H7: =COUNTIFS(花名册!B:B,$A$7,花名册!J:J,B7,花名册!R:R,"有")+COUNTIFS(花名册!B:B,$A$7,花名册!J:J,"注册人员",花名册!R:R,"有") -> 0 | I7: =COUNTIFS(花名册!$B:$B,$A$7,花名册!$J:$J,$B7,花名册!S:S,"有")+COUNTIFS(花名册!$B:$B,$A$7,花名册!$J:$J,"注册人员",花名册!S:S,"有") -> 0 | J7: {=COUNTIFS(花名册!$B:$B,$A$7,花名册!$J:$J,$B7,花名册!T:T,"有")+COUNTIFS(花名册!$B:$B,$A$7,花名册!$J:$J,“注册人员”,花名册!T:T,"有")} -> 0 | K7: =COUNTIFS(花名册!$B:$B,$A$7,花名册!$J:$J,$B7,花名册!U:U,"有")+COUNTIFS(花名册!$B:$B,$A$7,花名册!$J:$J,"注册人员",花名册!U:U,"有") -> 0 | L7: =COUNTIFS(花名册!$B:$B,$A$7,花名册!$J:$J,$B7,花名册!V:V,"有")+COUNTIFS(花名册!$B:$B,$A$7,花名册!$J:$J,"注册人员",花名册!V:V,"有") -> 0 | M7: =COUNTIFS(花名册!$B:$B,$A$7,花名册!$J:$J,$B7,花名册!W:W,"有")+(COUNTIFS(花名册!$B:$B,$A$7,花名册!$J:$J,"注册人员",花名册!W:W,"有")) -> 0 | N7: =COUNTIFS(花名册!$B:$B,$A$7,花名册!$J:$J,$B7,花名册!X:X,"有")+COUNTIFS(花名册!$B:$B,$A$7,花名册!$J:$J,"注册人员",花名册!X:X,"有") -> 0
B8: 商务人员 | C8: =COUNTIFS(花名册!B:B,$A$7,花名册!J:J,B8) -> 0 | D8: =C8/$C$10 -> 0 | F8: =COUNTIFS(花名册!B:B,$A$7,花名册!N:N,"博士",花名册!B:B,$A$7,花名册!J:J,B8)+COUNTIFS(花名册!B:B,$A$7,花名册!N:N,"硕士",花名册!B:B,$A$7,花名册!J:J,B8)+COUNTIFS(花名册!B:B,$A$7,花名册!N:N,"本科",花名册!B:B,$A$7,花名册!J:J,B8) -> 0 | G8: =COUNTIFS(花名册!B:B,$A$7,花名册!N:N,"大专",花名册!J:J,B8) -> 0 | H8: =COUNTIFS(花名册!B:B,$A$7,花名册!J:J,B8,花名册!R:R,"有") -> 0 | I8: =COUNTIFS(花名册!$B:$B,$A$7,花名册!$J:$J,$B8,花名册!S:S,"有") -> 0 | J8: =COUNTIFS(花名册!$B:$B,$A$7,花名册!$J:$J,$B8,花名册!T:T,"有") -> 0 | K8: =COUNTIFS(花名册!$B:$B,$A$7,花名册!$J:$J,$B8,花名册!U:U,"有") -> 0 | L8: =COUNTIFS(花名册!$B:$B,$A$7,花名册!$J:$J,$B8,花名册!V:V,"有") -> 0 | M8: =COUNTIFS(花名册!$B:$B,$A$7,花名册!$J:$J,$B8,花名册!W:W,"有") -> 0 | N8: =COUNTIFS(花名册!$B:$B,$A$7,花名册!$J:$J,$B8,花名册!X:X,"有") -> 0
B9: 生产人员 | C9: =COUNTIFS(花名册!B:B,$A$7,花名册!J:J,B9) -> 0 | D9: =C9/$C$10 -> 0 | E9: 0 | F9: =COUNTIFS(花名册!B:B,$A$7,花名册!N:N,"博士",花名册!B:B,$A$7,花名册!J:J,B9)+COUNTIFS(花名册!B:B,$A$7,花名册!N:N,"硕士",花名册!B:B,$A$7,花名册!J:J,B9)+COUNTIFS(花名册!B:B,$A$7,花名册!N:N,"本科",花名册!B:B,$A$7,花名册!J:J,B9) -> 0 | G9: =COUNTIFS(花名册!B:B,$A$7,花名册!N:N,"大专",花名册!J:J,B9) -> 0 | H9: =COUNTIFS(花名册!B:B,$A$7,花名册!J:J,B9,花名册!R:R,"有") -> 0 | I9: =COUNTIFS(花名册!$B:$B,$A$7,花名册!$J:$J,$B9,花名册!S:S,"有") -> 0 | J9: =COUNTIFS(花名册!$B:$B,$A$7,花名册!$J:$J,$B9,花名册!T:T,"有") -> 0 | K9: =COUNTIFS(花名册!$B:$B,$A$7,花名册!$J:$J,$B9,花名册!U:U,"有") -> 0 | L9: =COUNTIFS(花名册!$B:$B,$A$7,花名册!$J:$J,$B9,花名册!V:V,"有") -> 0 | M9: =COUNTIFS(花名册!$B:$B,$A$7,花名册!$J:$J,$B9,花名册!W:W,"有") -> 0 | N9: =COUNTIFS(花名册!$B:$B,$A$7,花名册!$J:$J,$B9,花名册!X:X,"有") -> 0
B10: 小计 | C10: =SUM(C7:C9) -> 3 | E10: =(C10-57)/57 -> -0.94736842 | F10: =SUM(F7:F9) -> 4 | G10: =SUM(G7:G9) -> 1 | H10: =SUM(H7:H9) -> 0 | I10: =SUM(I7:I9) -> 0 | J10: =SUM(J7:J9) -> 0 | K10: =SUM(K7:K9) -> 0 | L10: =SUM(L7:L9) -> 0 | M10: =SUM(M7:M9) -> 0 | N10: =SUM(N7:N9) -> 0
A11: 运营商事业部 | B11: 管理人员 | C11: =COUNTIFS(花名册!B:B,$A$11,花名册!J:J,B11) -> 0 | D11: =C11/$C$14 -> #DIV/0! | E11: =(C11-103)/103 -> -1 | F11: =COUNTIFS(花名册!B:B,$A$11,花名册!N:N,"博士",花名册!B:B,$A$11,花名册!J:J,B11)+COUNTIFS(花名册!B:B,$A$11,花名册!N:N,"硕士",花名册!B:B,$A$11,花名册!J:J,B11)+COUNTIFS(花名册!B:B,$A$11,花名册!N:N,"本科",花名册!B:B,$A$11,花名册!J:J,B11)+COUNTIFS(花名册!B:B,$A$11,花名册!N:N,"博士",花名册!B:B,$A$11,花名册!J:J,"后台人员")+COUNTIFS(花名册!B:B,$A$11,花名册!N:N,"硕士",花名册!B:B,$A$11,花名册!J:J,"后台人员")+COUNTIFS(花名册!B:B,$A$11,花名册!N:N,"本科",花名册!B:B,$A$11,花名册!J:J,"后台人员") -> 0 | G11: =COUNTIFS(花名册!B:B,$A$11,花名册!N:N,"大专",花名册!J:J,B11) -> 0 | H11: =COUNTIFS(花名册!B:B,$A$11,花名册!J:J,B11,花名册!R:R,"有") -> 0 | I11: =COUNTIFS(花名册!$B:$B,$A$11,花名册!$J:$J,$B11,花名册!S:S,"有") -> 0 | J11: =COUNTIFS(花名册!$B:$B,$A$11,花名册!$J:$J,$B11,花名册!T:T,"有") -> 0 | K11: =COUNTIFS(花名册!$B:$B,$A$11,花名册!$J:$J,$B11,花名册!U:U,"有") -> 0 | L11: =COUNTIFS(花名册!$B:$B,$A$11,花名册!$J:$J,$B11,花名册!V:V,"有") -> 0 | M11: =COUNTIFS(花名册!$B:$B,$A$11,花名册!$J:$J,$B11,花名册!W:W,"有") -> 0 | N11: =COUNTIFS(花名册!$B:$B,$A$11,花名册!$J:$J,$B11,花名册!X:X,"有") -> 0
B12: 商务人员 | C12: =COUNTIFS(花名册!B:B,$A$11,花名册!J:J,B12) -> 0 | D12: =C12/$C$14 -> #DIV/0! | E12: =(C12-9)/9 -> -1 | F12: =COUNTIFS(花名册!B:B,$A$11,花名册!N:N,"博士",花名册!B:B,$A$11,花名册!J:J,B12)+COUNTIFS(花名册!B:B,$A$11,花名册!N:N,"硕士",花名册!B:B,$A$11,花名册!J:J,B12)+COUNTIFS(花名册!B:B,$A$11,花名册!N:N,"本科",花名册!B:B,$A$11,花名册!J:J,B12) -> 0 | G12: =COUNTIFS(花名册!B:B,$A$11,花名册!N:N,"大专",花名册!J:J,B12) -> 0 | H12: =COUNTIFS(花名册!B:B,$A$11,花名册!J:J,B12,花名册!R:R,"有") -> 0 | I12: =COUNTIFS(花名册!$B:$B,$A$11,花名册!$J:$J,$B12,花名册!S:S,"有") -> 0 | J12: =COUNTIFS(花名册!$B:$B,$A$11,花名册!$J:$J,$B12,花名册!T:T,"有") -> 0 | K12: =COUNTIFS(花名册!$B:$B,$A$11,花名册!$J:$J,$B12,花名册!U:U,"有") -> 0 | L12: =COUNTIFS(花名册!$B:$B,$A$11,花名册!$J:$J,$B12,花名册!V:V,"有") -> 0 | M12: =COUNTIFS(花名册!$B:$B,$A$11,花名册!$J:$J,$B12,花名册!W:W,"有") -> 0 | N12: =COUNTIFS(花名册!$B:$B,$A$11,花名册!$J:$J,$B12,花名册!X:X,"有") -> 0
B13: 生产人员 | C13: =COUNTIFS(花名册!B:B,$A$11,花名册!J:J,B13)+COUNTIFS(花名册!B:B,$A$11,花名册!J:J,"后台人员") -> 0 | D13: =C13/$C$14 -> #DIV/0! | E13: =(C13-2372)/2372 -> -1 | F13: =COUNTIFS(花名册!B:B,$A$11,花名册!N:N,"博士",花名册!B:B,$A$11,花名册!J:J,B13)+COUNTIFS(花名册!B:B,$A$11,花名册!N:N,"硕士",花名册!B:B,$A$11,花名册!J:J,B13)+COUNTIFS(花名册!B:B,$A$11,花名册!N:N,"本科",花名册!B:B,$A$11,花名册!J:J,B13) -> 0 | G13: =COUNTIFS(花名册!B:B,$A$11,花名册!N:N,"大专",花名册!J:J,B13)+COUNTIFS(花名册!B:B,$A$11,花名册!N:N,"大专",花名册!J:J,"后台人员") -> 0 | H13: =COUNTIFS(花名册!B:B,$A$11,花名册!J:J,B13,花名册!R:R,"有")+COUNTIFS(花名册!B:B,$A$11,花名册!J:J,"后台人员",花名册!R:R,"有") -> 0 | I13: =COUNTIFS(花名册!$B:$B,$A$11,花名册!$J:$J,$B13,花名册!S:S,"有")+COUNTIFS(花名册!$B:$B,$A$11,花名册!$J:$J,"后台人员",花名册!S:S,"有") -> 0 | J13: =COUNTIFS(花名册!$B:$B,$A$11,花名册!$J:$J,$B13,花名册!T:T,"有")+COUNTIFS(花名册!$B:$B,$A$11,花名册!$J:$J,"后台人员",花名册!T:T,"有") -> 0 | K13: =COUNTIFS(花名册!$B:$B,$A$11,花名册!$J:$J,$B13,花名册!U:U,"有")+COUNTIFS(花名册!$B:$B,$A$11,花名册!$J:$J,"后台人员",花名册!U:U,"有") -> 0 | L13: =COUNTIFS(花名册!$B:$B,$A$11,花名册!$J:$J,$B13,花名册!V:V,"有")+COUNTIFS(花名册!$B:$B,$A$11,花名册!$J:$J,"后台人员",花名册!V:V,"有") -> 0 | M13: =COUNTIFS(花名册!$B:$B,$A$11,花名册!$J:$J,$B13,花名册!W:W,"有")+COUNTIFS(花名册!$B:$B,$A$11,花名册!$J:$J,"后台人员",花名册!W:W,"有") -> 0 | N13: =COUNTIFS(花名册!$B:$B,$A$11,花名册!$J:$J,$B13,花名册!X:X,"有")+COUNTIFS(花名册!$B:$B,$A$11,花名册!$J:$J,"后台人员",花名册!X:X,"有") -> 0
B14: 小计 | C14: =SUM(C11:C13) -> 0 | E14: =(C14-2484)/2484 -> -1 | F14: =SUM(F11:F13) -> 0 | G14: =SUM(G11:G13) -> 0 | H14: =SUM(H11:H13) -> 0 | I14: =SUM(I11:I13) -> 0 | J14: =SUM(J11:J13) -> 0 | K14: =SUM(K11:K13) -> 0 | L14: =SUM(L11:L13) -> 0 | M14: =SUM(M11:M13) -> 0 | N14: =SUM(N11:N13) -> 0
A15: 公路事业部 | B15: 管理人员 | C15: =COUNTIFS(花名册!B:B,$A$15,花名册!J:J,B15) -> 0 | D15: =C15/$C$18 -> 0 | E15: =(C15-5)/5 -> -1 | F15: =COUNTIFS(花名册!B:B,$A$15,花名册!N:N,"博士",花名册!B:B,$A$15,花名册!J:J,B15)+COUNTIFS(花名册!B:B,$A$15,花名册!N:N,"硕士",花名册!B:B,$A$15,花名册!J:J,B15)+COUNTIFS(花名册!B:B,$A$15,花名册!N:N,"本科",花名册!B:B,$A$15,花名册!J:J,B15) -> 0 | G15: =COUNTIFS(花名册!B:B,$A$15,花名册!N:N,"大专",花名册!J:J,B15) -> 0 | H15: =COUNTIFS(花名册!B:B,$A$15,花名册!J:J,B15,花名册!R:R,"有") -> 0 | I15: =COUNTIFS(花名册!$B:$B,$A$15,花名册!$J:$J,$B15,花名册!S:S,"有") -> 0 | J15: =COUNTIFS(花名册!$B:$B,$A$15,花名册!$J:$J,$B15,花名册!T:T,"有") -> 0 | K15: =COUNTIFS(花名册!$B:$B,$A$15,花名册!$J:$J,$B15,花名册!U:U,"有") -> 0 | L15: =COUNTIFS(花名册!$B:$B,$A$15,花名册!$J:$J,$B15,花名册!V:V,"有") -> 0 | M15: =COUNTIFS(花名册!$B:$B,$A$15,花名册!$J:$J,$B15,花名册!W:W,"有") -> 0 | N15: =COUNTIFS(花名册!$B:$B,$A$15,花名册!$J:$J,$B15,花名册!X:X,"有") -> 0
B16: 商务人员 | C16: =COUNTIFS(花名册!B:B,$A$15,花名册!J:J,B16) -> 0 | D16: =C16/$C$18 -> 0 | F16: =COUNTIFS(花名册!B:B,$A$15,花名册!N:N,"博士",花名册!B:B,$A$15,花名册!J:J,B16)+COUNTIFS(花名册!B:B,$A$15,花名册!N:N,"硕士",花名册!B:B,$A$15,花名册!J:J,B16)+COUNTIFS(花名册!B:B,$A$15,花名册!N:N,"本科",花名册!B:B,$A$15,花名册!J:J,B16) -> 0 | G16: =COUNTIFS(花名册!B:B,$A$15,花名册!N:N,"大专",花名册!J:J,B16) -> 0 | H16: =COUNTIFS(花名册!B:B,$A$15,花名册!J:J,B16,花名册!R:R,"有") -> 0 | I16: =COUNTIFS(花名册!$B:$B,$A$15,花名册!$J:$J,$B16,花名册!S:S,"有") -> 0 | J16: =COUNTIFS(花名册!$B:$B,$A$15,花名册!$J:$J,$B16,花名册!T:T,"有") -> 0 | K16: =COUNTIFS(花名册!$B:$B,$A$15,花名册!$J:$J,$B16,花名册!U:U,"有") -> 0 | L16: =COUNTIFS(花名册!$B:$B,$A$15,花名册!$J:$J,$B16,花名册!V:V,"有") -> 0 | M16: =COUNTIFS(花名册!$B:$B,$A$15,花名册!$J:$J,$B16,花名册!W:W,"有") -> 0 | N16: =COUNTIFS(花名册!$B:$B,$A$15,花名册!$J:$J,$B16,花名册!X:X,"有") -> 0
B17: 生产人员 | C17: =COUNTIFS(花名册!B:B,$A$15,花名册!J:J,B17)-3 -> -3 | D17: =C17/$C$18 -> 1 | E17: =(C17-78)/78 -> -1.0384615 | F17: =COUNTIFS(花名册!B:B,$A$15,花名册!N:N,"博士",花名册!B:B,$A$15,花名册!J:J,B17)+COUNTIFS(花名册!B:B,$A$15,花名册!N:N,"硕士",花名册!B:B,$A$15,花名册!J:J,B17)+COUNTIFS(花名册!B:B,$A$15,花名册!N:N,"本科",花名册!B:B,$A$15,花名册!J:J,B17) -> 0 | G17: =COUNTIFS(花名册!B:B,$A$15,花名册!N:N,"大专",花名册!J:J,B17) -> 0 | H17: =COUNTIFS(花名册!B:B,$A$15,花名册!J:J,B17,花名册!R:R,"有")+COUNTIFS(花名册!B:B,$A$15,花名册!J:J,"后台人员",花名册!R:R,"有") -> 0 | I17: =COUNTIFS(花名册!$B:$B,$A$15,花名册!$J:$J,$B17,花名册!S:S,"有") -> 0 | J17: =COUNTIFS(花名册!$B:$B,$A$15,花名册!$J:$J,$B17,花名册!T:T,"有") -> 0 | K17: =COUNTIFS(花名册!$B:$B,$A$15,花名册!$J:$J,$B17,花名册!U:U,"有") -> 0 | L17: =COUNTIFS(花名册!$B:$B,$A$15,花名册!$J:$J,$B17,花名册!V:V,"有") -> 0 | M17: =COUNTIFS(花名册!$B:$B,$A$15,花名册!$J:$J,$B17,花名册!W:W,"有") -> 0 | N17: =COUNTIFS(花名册!$B:$B,$A$15,花名册!$J:$J,$B17,花名册!X:X,"有") -> 0
B18: 小计 | C18: =SUM(C15:C17) -> -3 | E18: =(C18-83)/83 -> -1.0361446 | F18: =SUM(F15:F17) -> 0 | G18: =SUM(G15:G17) -> 0 | H18: =SUM(H15:H17) -> 0 | I18: =SUM(I15:I17) -> 0 | J18: =SUM(J15:J17) -> 0 | K18: =SUM(K15:K17) -> 0 | L18: =SUM(L15:L17) -> 0 | M18: =SUM(M15:M17) -> 0 | N18: =SUM(N15:N17) -> 0
A19: 轨道交通事业部 | B19: 管理人员 | C19: =COUNTIFS(花名册!B:B,$A$19,花名册!J:J,B19) -> 0 | D19: =C19/$C$22 -> #DIV/0! | F19: =COUNTIFS(花名册!B:B,$A$19,花名册!N:N,"博士",花名册!B:B,$A$19,花名册!J:J,B19)+COUNTIFS(花名册!B:B,$A$19,花名册!N:N,"硕士",花名册!B:B,$A$19,花名册!J:J,B19)+COUNTIFS(花名册!B:B,$A$19,花名册!N:N,"本科",花名册!B:B,$A$19,花名册!J:J,B19) -> 0 | G19: =COUNTIFS(花名册!B:B,$A$19,花名册!N:N,"大专",花名册!J:J,B19) -> 0 | H19: =COUNTIFS(花名册!B:B,$A$19,花名册!J:J,B19,花名册!R:R,"有") -> 0 | I19: =COUNTIFS(花名册!$B:$B,$A$19,花名册!$J:$J,$B19,花名册!S:S,"有") -> 0 | J19: =COUNTIFS(花名册!$B:$B,$A$19,花名册!$J:$J,$B19,花名册!T:T,"有") -> 0 | K19: =COUNTIFS(花名册!$B:$B,$A$19,花名册!$J:$J,$B19,花名册!U:U,"有") -> 0 | L19: =COUNTIFS(花名册!$B:$B,$A$19,花名册!$J:$J,$B19,花名册!V:V,"有") -> 0 | M19: =COUNTIFS(花名册!$B:$B,$A$19,花名册!$J:$J,$B19,花名册!W:W,"有") -> 0 | N19: =COUNTIFS(花名册!$B:$B,$A$19,花名册!$J:$J,$B19,花名册!X:X,"有") -> 0
B20: 商务人员 | C20: =COUNTIFS(花名册!B:B,$A$19,花名册!J:J,B20) -> 0 | D20: =C20/$C$22 -> #DIV/0! | F20: =COUNTIFS(花名册!B:B,$A$19,花名册!N:N,"博士",花名册!B:B,$A$19,花名册!J:J,B20)+COUNTIFS(花名册!B:B,$A$19,花名册!N:N,"硕士",花名册!B:B,$A$19,花名册!J:J,B20)+COUNTIFS(花名册!B:B,$A$19,花名册!N:N,"本科",花名册!B:B,$A$19,花名册!J:J,B20) -> 0 | G20: =COUNTIFS(花名册!B:B,$A$19,花名册!N:N,"大专",花名册!J:J,B20) -> 0 | H20: =COUNTIFS(花名册!B:B,$A$19,花名册!J:J,B20,花名册!R:R,"有") -> 0 | I20: =COUNTIFS(花名册!$B:$B,$A$19,花名册!$J:$J,$B20,花名册!S:S,"有") -> 0 | J20: =COUNTIFS(花名册!$B:$B,$A$19,花名册!$J:$J,$B20,花名册!T:T,"有") -> 0 | K20: =COUNTIFS(花名册!$B:$B,$A$19,花名册!$J:$J,$B20,花名册!U:U,"有") -> 0 | L20: =COUNTIFS(花名册!$B:$B,$A$19,花名册!$J:$J,$B20,花名册!V:V,"有") -> 0 | M20: =COUNTIFS(花名册!$B:$B,$A$19,花名册!$J:$J,$B20,花名册!W:W,"有") -> 0 | N20: =COUNTIFS(花名册!$B:$B,$A$19,花名册!$J:$J,$B20,花名册!X:X,"有") -> 0
B21: 生产人员 | C21: =COUNTIFS(花名册!B:B,$A$19,花名册!J:J,B21) -> 0 | D21: =C21/$C$22 -> #DIV/0! | F21: =COUNTIFS(花名册!B:B,$A$19,花名册!N:N,"博士",花名册!B:B,$A$19,花名册!J:J,B21)+COUNTIFS(花名册!B:B,$A$19,花名册!N:N,"硕士",花名册!B:B,$A$19,花名册!J:J,B21)+COUNTIFS(花名册!B:B,$A$19,花名册!N:N,"本科",花名册!B:B,$A$19,花名册!J:J,B21) -> 0 | G21: =COUNTIFS(花名册!B:B,$A$19,花名册!N:N,"大专",花名册!J:J,B21) -> 0 | H21: =COUNTIFS(花名册!B:B,$A$19,花名册!J:J,B21,花名册!R:R,"有")+COUNTIFS(花名册!B:B,$A$19,花名册!J:J,"后台人员",花名册!R:R,"有") -> 0 | I21: =COUNTIFS(花名册!$B:$B,$A$19,花名册!$J:$J,$B21,花名册!S:S,"有") -> 0 | J21: =COUNTIFS(花名册!$B:$B,$A$19,花名册!$J:$J,$B21,花名册!T:T,"有") -> 0 | K21: =COUNTIFS(花名册!$B:$B,$A$19,花名册!$J:$J,$B21,花名册!U:U,"有") -> 0 | L21: =COUNTIFS(花名册!$B:$B,$A$19,花名册!$J:$J,$B21,花名册!V:V,"有") -> 0 | M21: =COUNTIFS(花名册!$B:$B,$A$19,花名册!$J:$J,$B21,花名册!W:W,"有") -> 0 | N21: =COUNTIFS(花名册!$B:$B,$A$19,花名册!$J:$J,$B21,花名册!X:X,"有") -> 0
B22: 小计 | C22: =SUM(C19:C21) -> 0 | E22: =SUM(E19:E21) -> 0 | F22: =SUM(F19:F21) -> 0 | G22: =SUM(G19:G21) -> 0 | H22: =SUM(H19:H21) -> 0 | I22: =SUM(I19:I21) -> 0 | J22: =SUM(J19:J21) -> 0 | K22: =SUM(K19:K21) -> 0 | L22: =SUM(L19:L21) -> 0 | ... N22: =SUM(N19:N21) -> 0
A23: 电力事业部 | B23: 管理人员 | C23: =COUNTIFS(花名册!B:B,$A$23,花名册!J:J,B23) -> 0 | D23: =C23/$C$26 -> #DIV/0! | E23: =(C23-1)/1 -> -1 | F23: =COUNTIFS(花名册!B:B,$A$23,花名册!N:N,"博士",花名册!B:B,$A$23,花名册!J:J,B23)+COUNTIFS(花名册!B:B,$A$23,花名册!N:N,"硕士",花名册!B:B,$A$23,花名册!J:J,B23)+COUNTIFS(花名册!B:B,$A$23,花名册!N:N,"本科",花名册!B:B,$A$23,花名册!J:J,B23) -> 0 | G23: =COUNTIFS(花名册!B:B,$A$23,花名册!N:N,"大专",花名册!J:J,B23) -> 0 | H23: =COUNTIFS(花名册!B:B,$A$23,花名册!J:J,B23,花名册!R:R,"有") -> 0 | I23: =COUNTIFS(花名册!$B:$B,$A$23,花名册!$J:$J,$B23,花名册!S:S,"有") -> 0 | J23: =COUNTIFS(花名册!$B:$B,$A$23,花名册!$J:$J,$B23,花名册!T:T,"有") -> 0 | K23: =COUNTIFS(花名册!$B:$B,$A$23,花名册!$J:$J,$B23,花名册!U:U,"有") -> 0 | L23: =COUNTIFS(花名册!$B:$B,$A$23,花名册!$J:$J,$B23,花名册!V:V,"有") -> 0 | M23: =COUNTIFS(花名册!$B:$B,$A$23,花名册!$J:$J,$B23,花名册!W:W,"有") -> 0 | N23: =COUNTIFS(花名册!$B:$B,$A$23,花名册!$J:$J,$B23,花名册!X:X,"有") -> 0
B24: 商务人员 | C24: =COUNTIFS(花名册!B:B,$A$23,花名册!J:J,B24) -> 0 | D24: =C24/$C$26 -> #DIV/0! | F24: =COUNTIFS(花名册!B:B,$A$23,花名册!N:N,"博士",花名册!B:B,$A$23,花名册!J:J,B24)+COUNTIFS(花名册!B:B,$A$23,花名册!N:N,"硕士",花名册!B:B,$A$23,花名册!J:J,B24)+COUNTIFS(花名册!B:B,$A$23,花名册!N:N,"本科",花名册!B:B,$A$23,花名册!J:J,B24) -> 0 | G24: =COUNTIFS(花名册!B:B,$A$23,花名册!N:N,"大专",花名册!J:J,B24) -> 0 | H24: =COUNTIFS(花名册!B:B,$A$23,花名册!J:J,B24,花名册!R:R,"有") -> 0 | I24: =COUNTIFS(花名册!$B:$B,$A$23,花名册!$J:$J,$B24,花名册!S:S,"有") -> 0 | J24: =COUNTIFS(花名册!$B:$B,$A$23,花名册!$J:$J,$B24,花名册!T:T,"有") -> 0 | K24: =COUNTIFS(花名册!$B:$B,$A$23,花名册!$J:$J,$B24,花名册!U:U,"有") -> 0 | L24: =COUNTIFS(花名册!$B:$B,$A$23,花名册!$J:$J,$B24,花名册!V:V,"有") -> 0 | M24: =COUNTIFS(花名册!$B:$B,$A$23,花名册!$J:$J,$B24,花名册!W:W,"有") -> 0 | N24: =COUNTIFS(花名册!$B:$B,$A$23,花名册!$J:$J,$B24,花名册!X:X,"有") -> 0
B25: 生产人员 | C25: =COUNTIFS(花名册!B:B,$A$23,花名册!J:J,B25) -> 0 | D25: =C25/$C$26 -> #DIV/0! | F25: =COUNTIFS(花名册!B:B,$A$23,花名册!N:N,"博士",花名册!B:B,$A$23,花名册!J:J,B25)+COUNTIFS(花名册!B:B,$A$23,花名册!N:N,"硕士",花名册!B:B,$A$23,花名册!J:J,B25)+COUNTIFS(花名册!B:B,$A$23,花名册!N:N,"本科",花名册!B:B,$A$23,花名册!J:J,B25) -> 0 | G25: =COUNTIFS(花名册!B:B,$A$23,花名册!N:N,"大专",花名册!J:J,B25) -> 0 | H25: =COUNTIFS(花名册!B:B,$A$23,花名册!J:J,B25,花名册!R:R,"有")+COUNTIFS(花名册!B:B,$A$23,花名册!J:J,"后台人员",花名册!R:R,"有") -> 0 | I25: =COUNTIFS(花名册!$B:$B,$A$23,花名册!$J:$J,$B25,花名册!S:S,"有") -> 0 | J25: =COUNTIFS(花名册!$B:$B,$A$23,花名册!$J:$J,$B25,花名册!T:T,"有") -> 0 | K25: =COUNTIFS(花名册!$B:$B,$A$23,花名册!$J:$J,$B25,花名册!U:U,"有") -> 0 | L25: =COUNTIFS(花名册!$B:$B,$A$23,花名册!$J:$J,$B25,花名册!V:V,"有") -> 0 | M25: =COUNTIFS(花名册!$B:$B,$A$23,花名册!$J:$J,$B25,花名册!W:W,"有") -> 0 | N25: =COUNTIFS(花名册!$B:$B,$A$23,花名册!$J:$J,$B25,花名册!X:X,"有") -> 0
B26: 小计 | C26: =SUM(C23:C25) -> 0 | E26: =(C26-1)/1 -> -1 | F26: =SUM(F23:F25) -> 0 | G26: =SUM(G23:G25) -> 0 | H26: =SUM(H23:H25) -> 0 | I26: =SUM(I23:I25) -> 0 | J26: =SUM(J23:J25) -> 0 | K26: =SUM(K23:K25) -> 0 | L26: =SUM(L23:L25) -> 0 | M26: =SUM(M23:M25) -> 0 | N26: =SUM(N23:N25) -> 0
A27: 政企事业部 | B27: 管理人员 | C27: =COUNTIFS(花名册!B:B,$A$27,花名册!J:J,B27) -> 0 | D27: =C27/$C$30 -> #DIV/0! | E27: =(C27-3)/3 -> -1 | F27: =COUNTIFS(花名册!B:B,$A$27,花名册!N:N,"博士",花名册!B:B,$A$27,花名册!J:J,B27)+COUNTIFS(花名册!B:B,$A$27,花名册!N:N,"硕士",花名册!B:B,$A$27,花名册!J:J,B27)+COUNTIFS(花名册!B:B,$A$27,花名册!N:N,"本科",花名册!B:B,$A$27,花名册!J:J,B27) -> 0 | G27: =COUNTIFS(花名册!B:B,$A$27,花名册!N:N,"大专",花名册!J:J,B27) -> 0 | H27: =COUNTIFS(花名册!B:B,$A$27,花名册!J:J,B27,花名册!R:R,"有") -> 0 | I27: =COUNTIFS(花名册!$B:$B,$A$27,花名册!$J:$J,$B27,花名册!S:S,"有") -> 0 | J27: =COUNTIFS(花名册!$B:$B,$A$27,花名册!$J:$J,$B27,花名册!T:T,"有") -> 0 | K27: =COUNTIFS(花名册!$B:$B,$A$27,花名册!$J:$J,$B27,花名册!U:U,"有") -> 0 | L27: =COUNTIFS(花名册!$B:$B,$A$27,花名册!$J:$J,$B27,花名册!V:V,"有") -> 0 | M27: =COUNTIFS(花名册!$B:$B,$A$27,花名册!$J:$J,$B27,花名册!W:W,"有") -> 0 | N27: =COUNTIFS(花名册!$B:$B,$A$27,花名册!$J:$J,$B27,花名册!X:X,"有") -> 0
B28: 商务人员 | C28: =COUNTIFS(花名册!B:B,$A$27,花名册!J:J,B28) -> 0 | D28: =C28/$C$30 -> #DIV/0! | F28: =COUNTIFS(花名册!B:B,$A$27,花名册!N:N,"博士",花名册!B:B,$A$27,花名册!J:J,B28)+COUNTIFS(花名册!B:B,$A$27,花名册!N:N,"硕士",花名册!B:B,$A$27,花名册!J:J,B28)+COUNTIFS(花名册!B:B,$A$27,花名册!N:N,"本科",花名册!B:B,$A$27,花名册!J:J,B28) -> 0 | G28: =COUNTIFS(花名册!B:B,$A$27,花名册!N:N,"大专",花名册!J:J,B28) -> 0 | H28: =COUNTIFS(花名册!B:B,$A$27,花名册!J:J,B28,花名册!R:R,"有") -> 0 | I28: =COUNTIFS(花名册!$B:$B,$A$27,花名册!$J:$J,$B28,花名册!S:S,"有") -> 0 | J28: =COUNTIFS(花名册!$B:$B,$A$27,花名册!$J:$J,$B28,花名册!T:T,"有") -> 0 | K28: =COUNTIFS(花名册!$B:$B,$A$27,花名册!$J:$J,$B28,花名册!U:U,"有") -> 0 | L28: =COUNTIFS(花名册!$B:$B,$A$27,花名册!$J:$J,$B28,花名册!V:V,"有") -> 0 | M28: =COUNTIFS(花名册!$B:$B,$A$27,花名册!$J:$J,$B28,花名册!W:W,"有") -> 0 | N28: =COUNTIFS(花名册!$B:$B,$A$27,花名册!$J:$J,$B28,花名册!X:X,"有") -> 0
B29: 生产人员 | C29: =COUNTIFS(花名册!B:B,$A$27,花名册!J:J,B29) -> 0 | D29: =C29/$C$30 -> #DIV/0! | F29: =COUNTIFS(花名册!B:B,$A$27,花名册!N:N,"博士",花名册!B:B,$A$27,花名册!J:J,B29)+COUNTIFS(花名册!B:B,$A$27,花名册!N:N,"硕士",花名册!B:B,$A$27,花名册!J:J,B29)+COUNTIFS(花名册!B:B,$A$27,花名册!N:N,"本科",花名册!B:B,$A$27,花名册!J:J,B29) -> 0 | G29: =COUNTIFS(花名册!B:B,$A$27,花名册!N:N,"大专",花名册!J:J,B29) -> 0 | H29: =COUNTIFS(花名册!B:B,$A$27,花名册!J:J,B29,花名册!R:R,"有")+COUNTIFS(花名册!B:B,$A$27,花名册!J:J,"后台人员",花名册!R:R,"有") -> 0 | I29: =COUNTIFS(花名册!$B:$B,$A$27,花名册!$J:$J,$B29,花名册!S:S,"有") -> 0 | J29: =COUNTIFS(花名册!$B:$B,$A$27,花名册!$J:$J,$B29,花名册!T:T,"有") -> 0 | K29: =COUNTIFS(花名册!$B:$B,$A$27,花名册!$J:$J,$B29,花名册!U:U,"有") -> 0 | L29: =COUNTIFS(花名册!$B:$B,$A$27,花名册!$J:$J,$B29,花名册!V:V,"有") -> 0 | M29: =COUNTIFS(花名册!$B:$B,$A$27,花名册!$J:$J,$B29,花名册!W:W,"有") -> 0 | N29: =COUNTIFS(花名册!$B:$B,$A$27,花名册!$J:$J,$B29,花名册!X:X,"有") -> 0
B30: 小计 | C30: =SUM(C27:C29) -> 0 | E30: =(C30-3)/3 -> -1 | F30: =SUM(F27:F29) -> 0 | G30: =SUM(G27:G29) -> 0 | H30: =SUM(H27:H29) -> 0 | I30: =SUM(I27:I29) -> 0 | J30: =SUM(J27:J29) -> 0 | K30: =SUM(K27:K29) -> 0 | L30: =SUM(L27:L29) -> 0 | M30: =SUM(M27:M29) -> 0 | N30: =SUM(N27:N29) -> 0
A31: 装备事业部 | B31: 管理人员 | C31: =COUNTIFS(花名册!B:B,$A$31,花名册!J:J,B31) -> 0 | D31: =C31/$C$34 -> #DIV/0! | E31: =(C31-4)/4 -> -1 | F31: =COUNTIFS(花名册!B:B,$A$31,花名册!N:N,"博士",花名册!B:B,$A$31,花名册!J:J,B31)+COUNTIFS(花名册!B:B,$A$31,花名册!N:N,"硕士",花名册!B:B,$A$31,花名册!J:J,B31)+COUNTIFS(花名册!B:B,$A$31,花名册!N:N,"本科",花名册!B:B,$A$31,花名册!J:J,B31) -> 0 | G31: =COUNTIFS(花名册!B:B,$A$31,花名册!N:N,"大专",花名册!J:J,B31) -> 0 | H31: =COUNTIFS(花名册!B:B,$A$31,花名册!J:J,B31,花名册!R:R,"有") -> 0 | I31: =COUNTIFS(花名册!$B:$B,$A$31,花名册!$J:$J,$B31,花名册!S:S,"有") -> 0 | J31: =COUNTIFS(花名册!$B:$B,$A$31,花名册!$J:$J,$B31,花名册!T:T,"有") -> 0 | K31: =COUNTIFS(花名册!$B:$B,$A$31,花名册!$J:$J,$B31,花名册!U:U,"有") -> 0 | L31: =COUNTIFS(花名册!$B:$B,$A$31,花名册!$J:$J,$B31,花名册!V:V,"有") -> 0 | M31: =COUNTIFS(花名册!$B:$B,$A$31,花名册!$J:$J,$B31,花名册!W:W,"有") -> 0 | N31: =COUNTIFS(花名册!$B:$B,$A$31,花名册!$J:$J,$B31,花名册!X:X,"有") -> 0
B32: 商务人员 | C32: =COUNTIFS(花名册!B:B,$A$31,花名册!J:J,B32) -> 0 | D32: =C32/$C$34 -> #DIV/0! | F32: =COUNTIFS(花名册!B:B,$A$31,花名册!N:N,"博士",花名册!B:B,$A$31,花名册!J:J,B32)+COUNTIFS(花名册!B:B,$A$31,花名册!N:N,"硕士",花名册!B:B,$A$31,花名册!J:J,B32)+COUNTIFS(花名册!B:B,$A$31,花名册!N:N,"本科",花名册!B:B,$A$31,花名册!J:J,B32) -> 0 | G32: =COUNTIFS(花名册!B:B,$A$31,花名册!N:N,"大专",花名册!J:J,B32) -> 0 | H32: =COUNTIFS(花名册!B:B,$A$31,花名册!J:J,B32,花名册!R:R,"有") -> 0 | I32: =COUNTIFS(花名册!$B:$B,$A$31,花名册!$J:$J,$B32,花名册!S:S,"有") -> 0 | J32: =COUNTIFS(花名册!$B:$B,$A$31,花名册!$J:$J,$B32,花名册!T:T,"有") -> 0 | K32: =COUNTIFS(花名册!$B:$B,$A$31,花名册!$J:$J,$B32,花名册!U:U,"有") -> 0 | L32: =COUNTIFS(花名册!$B:$B,$A$31,花名册!$J:$J,$B32,花名册!V:V,"有") -> 0 | M32: =COUNTIFS(花名册!$B:$B,$A$31,花名册!$J:$J,$B32,花名册!W:W,"有") -> 0 | N32: =COUNTIFS(花名册!$B:$B,$A$31,花名册!$J:$J,$B32,花名册!X:X,"有") -> 0
B33: 生产人员 | C33: =COUNTIFS(花名册!B:B,$A$31,花名册!J:J,B33) -> 0 | D33: =C33/$C$34 -> #DIV/0! | F33: =COUNTIFS(花名册!B:B,$A$31,花名册!N:N,"博士",花名册!B:B,$A$31,花名册!J:J,B33)+COUNTIFS(花名册!B:B,$A$31,花名册!N:N,"硕士",花名册!B:B,$A$31,花名册!J:J,B33)+COUNTIFS(花名册!B:B,$A$31,花名册!N:N,"本科",花名册!B:B,$A$31,花名册!J:J,B33) -> 0 | G33: =COUNTIFS(花名册!B:B,$A$31,花名册!N:N,"大专",花名册!J:J,B33) -> 0 | H33: =COUNTIFS(花名册!B:B,$A$31,花名册!J:J,B33,花名册!R:R,"有")+COUNTIFS(花名册!B:B,$A$31,花名册!J:J,"后台人员",花名册!R:R,"有") -> 0 | I33: =COUNTIFS(花名册!$B:$B,$A$31,花名册!$J:$J,$B33,花名册!S:S,"有") -> 0 | J33: =COUNTIFS(花名册!$B:$B,$A$31,花名册!$J:$J,$B33,花名册!T:T,"有") -> 0 | K33: =COUNTIFS(花名册!$B:$B,$A$31,花名册!$J:$J,$B33,花名册!U:U,"有") -> 0 | L33: =COUNTIFS(花名册!$B:$B,$A$31,花名册!$J:$J,$B33,花名册!V:V,"有") -> 0 | M33: =COUNTIFS(花名册!$B:$B,$A$31,花名册!$J:$J,$B33,花名册!W:W,"有") -> 0 | N33: =COUNTIFS(花名册!$B:$B,$A$31,花名册!$J:$J,$B33,花名册!X:X,"有") -> 0
B34: 小计 | C34: =SUM(C31:C33) -> 0 | E34: =(C34-4)/4 -> -1 | F34: =SUM(F31:F33) -> 0 | G34: =SUM(G31:G33) -> 0 | H34: =SUM(H31:H33) -> 0 | I34: =SUM(I31:I33) -> 0 | J34: =SUM(J31:J33) -> 0 | K34: =SUM(K31:K33) -> 0 | L34: =SUM(L31:L33) -> 0 | M34: =SUM(M31:M33) -> 0 | N34: =SUM(N31:N33) -> 0
A35: 低空经济事业部 | B35: 管理人员 | C35: =COUNTIFS(花名册!B:B,$A$35,花名册!J:J,B35) -> 0 | D35: =C35/$C$38 -> #DIV/0! | E35: =(C35-1)/1 -> -1 | F35: =COUNTIFS(花名册!B:B,$A$35,花名册!N:N,"博士",花名册!B:B,$A$35,花名册!J:J,B35)+COUNTIFS(花名册!B:B,$A$35,花名册!N:N,"硕士",花名册!B:B,$A$35,花名册!J:J,B35)+COUNTIFS(花名册!B:B,$A$35,花名册!N:N,"本科",花名册!B:B,$A$35,花名册!J:J,B35) -> 0 | G35: =COUNTIFS(花名册!B:B,$A$35,花名册!N:N,"大专",花名册!J:J,B35) -> 0 | H35: =COUNTIFS(花名册!B:B,$A$35,花名册!J:J,B35,花名册!R:R,"有") -> 0 | I35: =COUNTIFS(花名册!$B:$B,$A$35,花名册!$J:$J,$B35,花名册!S:S,"有") -> 0 | J35: =COUNTIFS(花名册!$B:$B,$A$35,花名册!$J:$J,$B35,花名册!T:T,"有") -> 0 | K35: =COUNTIFS(花名册!$B:$B,$A$35,花名册!$J:$J,$B35,花名册!U:U,"有") -> 0 | L35: =COUNTIFS(花名册!$B:$B,$A$35,花名册!$J:$J,$B35,花名册!V:V,"有") -> 0 | M35: =COUNTIFS(花名册!$B:$B,$A$35,花名册!$J:$J,$B35,花名册!W:W,"有") -> 0 | N35: =COUNTIFS(花名册!$B:$B,$A$35,花名册!$J:$J,$B35,花名册!X:X,"有") -> 0
B36: 商务人员 | C36: =COUNTIFS(花名册!B:B,$A$35,花名册!J:J,B36) -> 0 | D36: =C36/$C$38 -> #DIV/0! | F36: =COUNTIFS(花名册!B:B,$A$35,花名册!N:N,"博士",花名册!B:B,$A$35,花名册!J:J,B36)+COUNTIFS(花名册!B:B,$A$35,花名册!N:N,"硕士",花名册!B:B,$A$35,花名册!J:J,B36)+COUNTIFS(花名册!B:B,$A$35,花名册!N:N,"本科",花名册!B:B,$A$35,花名册!J:J,B36) -> 0 | G36: =COUNTIFS(花名册!B:B,$A$35,花名册!N:N,"大专",花名册!J:J,B36) -> 0 | H36: =COUNTIFS(花名册!B:B,$A$35,花名册!J:J,B36,花名册!R:R,"有") -> 0 | I36: =COUNTIFS(花名册!$B:$B,$A$35,花名册!$J:$J,$B36,花名册!S:S,"有") -> 0 | J36: =COUNTIFS(花名册!$B:$B,$A$35,花名册!$J:$J,$B36,花名册!T:T,"有") -> 0 | K36: =COUNTIFS(花名册!$B:$B,$A$35,花名册!$J:$J,$B36,花名册!U:U,"有") -> 0 | L36: =COUNTIFS(花名册!$B:$B,$A$35,花名册!$J:$J,$B36,花名册!V:V,"有") -> 0 | M36: =COUNTIFS(花名册!$B:$B,$A$35,花名册!$J:$J,$B36,花名册!W:W,"有") -> 0 | N36: =COUNTIFS(花名册!$B:$B,$A$35,花名册!$J:$J,$B36,花名册!X:X,"有") -> 0
B37: 生产人员 | C37: =COUNTIFS(花名册!B:B,$A$35,花名册!J:J,B37) -> 0 | D37: =C37/$C$38 -> #DIV/0! | F37: =COUNTIFS(花名册!B:B,$A$35,花名册!N:N,"博士",花名册!B:B,$A$35,花名册!J:J,B37)+COUNTIFS(花名册!B:B,$A$35,花名册!N:N,"硕士",花名册!B:B,$A$35,花名册!J:J,B37)+COUNTIFS(花名册!B:B,$A$35,花名册!N:N,"本科",花名册!B:B,$A$35,花名册!J:J,B37) -> 0 | G37: =COUNTIFS(花名册!B:B,$A$35,花名册!N:N,"大专",花名册!J:J,B37) -> 0 | H37: =COUNTIFS(花名册!B:B,$A$35,花名册!J:J,B37,花名册!R:R,"有")+COUNTIFS(花名册!B:B,$A$35,花名册!J:J,"后台人员",花名册!R:R,"有") -> 0 | I37: =COUNTIFS(花名册!$B:$B,$A$35,花名册!$J:$J,$B37,花名册!S:S,"有") -> 0 | J37: =COUNTIFS(花名册!$B:$B,$A$35,花名册!$J:$J,$B37,花名册!T:T,"有") -> 0 | K37: =COUNTIFS(花名册!$B:$B,$A$35,花名册!$J:$J,$B37,花名册!U:U,"有") -> 0 | L37: =COUNTIFS(花名册!$B:$B,$A$35,花名册!$J:$J,$B37,花名册!V:V,"有") -> 0 | M37: =COUNTIFS(花名册!$B:$B,$A$35,花名册!$J:$J,$B37,花名册!W:W,"有") -> 0 | N37: =COUNTIFS(花名册!$B:$B,$A$35,花名册!$J:$J,$B37,花名册!X:X,"有") -> 0
B38: 小计 | C38: =SUM(C35:C37) -> 0 | E38: =(C38-1)/1 -> -1 | F38: =SUM(F35:F37) -> 0 | G38: =SUM(G35:G37) -> 0 | H38: =SUM(H35:H37) -> 0 | I38: =SUM(I35:I37) -> 0 | J38: =SUM(J35:J37) -> 0 | K38: =SUM(K35:K37) -> 0 | L38: =SUM(L35:L37) -> 0 | M38: =SUM(M35:M37) -> 0 | N38: =SUM(N35:N37) -> 0

Sheet 运营商事业部（按项目分）
A1: 2026年4月人力资源数据分析表（运营商事业部）
A2: 部门/省、市 | C2: 专业 | D2: 4月人数 | E2: 4月产值 | F2: 人均产值 | G2: 4月网络数量 | H2: 人均维护网络数量 | I2: 4月薪酬（不含租车）（含社保） | J2: 人均薪酬
A3: 合计 | D3: =D4+D5+D11+D14+D19+D20+D21+D23+D24+D25+D30+D31+D32+D36+D37+D38+D41+D42+D44+D50+D51+D52+D53+D54+D55+D56+D43+D12+D13 -> 43 | F3: =E3/D3 -> 0 | G3: =G4+G5+G11+G14+G19+G20+G21+G23+G24+G25+G30+G31+G32+G36+G37+G38+G41+G42+G44+G50+G51+G52+G53+G54+G55+G56+G43+G12+G13 -> 0 | H3: =G3/D3 -> 0 | I3: =I4+I5+I11+I14+I19+I20+I21+I23+I24+I25+I30+I31+I32+I36+I37+I38+I41+I42+I44+I50+I51+I52+I53+I54+I55+I56+I43+I12+I13 -> 0 | J3: =I3/D3 -> 0
A4: 事业部本部（含标书室） | D4: =COUNTIFS(花名册!C:C,"运营商事业部")+COUNTIFS(花名册!C:C,"标书室") -> 16 | F4: =E4/D4 -> 0 | H4: =G4/D4 -> 0 | J4: =I4/D4 -> 0
A5: 江西 | B5: 江西省公司 | D5: =COUNTIFS(花名册!C:C,B5) -> 4 | F5: =E5/D5 -> 0 | H5: =G5/D5 -> 0 | J5: =I5/D5 -> 0
B6: 南昌 | D6: =COUNTIFS(花名册!C:C,B6) -> 11 | F6: =E6/D6 -> 0 | H6: =G6/D6 -> 0 | J6: =I6/D6 -> 0
B7: 上饶 | D7: =COUNTIFS(花名册!C:C,B7) -> 0 | F7: =E7/D7 -> #DIV/0! | H7: =G7/D7 -> #DIV/0! | J7: =I7/(D7-1) -> 0
B8: 九江 | D8: =COUNTIFS(花名册!C:C,B8) -> 11 | F8: =E8/D8 -> 0 | H8: =G8/D8 -> 0 | J8: =I8/D8 -> 0
B9: 抚州 | D9: =COUNTIFS(花名册!C:C,B9) -> 0 | F9: =E9/D9 -> #DIV/0! | H9: =G9/D9 -> #DIV/0! | J9: =I9/D9 -> #DIV/0!
B10: 鹰潭 | D10: =COUNTIFS(花名册!C:C,B10) -> 0 | F10: =E10/D10 -> #DIV/0! | H10: =G10/D10 -> #DIV/0! | J10: =I10/D10 -> #DIV/0!
B11: 代维合计 | D11: =SUM(D6:D10) -> 22 | E11: =SUM(E6:E10) -> 0 | F11: =E11/D11 -> 0 | G11: =SUM(G6:G10) -> 0 | H11: =G11/D11 -> 0 | I11: =SUM(I6:I10) -> 0 | J11: =I11/D11 -> 0
B12: 南昌有线宽带项目 | D12: =COUNTIFS(花名册!C:C,B12) -> 0 | J12: =I12/D12 -> #DIV/0!
B13: 上饶有线宽带项目 | D13: =COUNTIFS(花名册!C:C,B13) -> 0 | J13: =I13/D13 -> #DIV/0!
B14: 江西工程 | D14: =COUNTIFS(花名册!C:C,B14) -> 0 | F14: =E14/D14 -> #DIV/0! | H14: =G14/D14 -> #DIV/0! | J14: =I14/D14 -> #DIV/0!
A15: 广东 | D15: =COUNTIFS(花名册!C:C,B15) -> 0 | F15: =E15/D15 -> #DIV/0! | H15: =G15/D15 -> #DIV/0! | J15: =I15/D15 -> #DIV/0!
D16: =COUNTIFS(花名册!C:C,B16) -> 0 | F16: =E16/D16 -> #DIV/0! | H16: =G16/D16 -> #DIV/0! | J16: =I16/D16 -> #DIV/0!
D17: =COUNTIFS(花名册!C:C,B17) -> 0 | F17: =E17/D17 -> #DIV/0! | H17: =G17/D17 -> #DIV/0! | J17: =I17/D17 -> #DIV/0!
D18: =COUNTIFS(花名册!C:C,B18) -> 0 | F18: =E18/D18 -> #DIV/0! | H18: =G18/D18 -> #DIV/0! | J18: =I18/D18 -> #DIV/0!
B19: 代维合计 | D19: =SUM(D15:D18) -> 0 | E19: =SUM(E15:E18) -> 0 | F19: =E19/D19 -> #DIV/0! | G19: =SUM(G15:G18) -> 0 | H19: =G19/D19 -> #DIV/0! | I19: =SUM(I15:I18) -> 0 | J19: =I19/D19 -> #DIV/0!
B20: 广东工程 | D20: =COUNTIFS(花名册!C:C,B20) -> 0 | F20: =E20/D20 -> #DIV/0! | H20: =G20/D20 -> #DIV/0! | J20: =I20/D20 -> #DIV/0!
A21: 贵州 | D21: =COUNTIFS(花名册!C:C,B21) -> 0 | F21: =E21/D21 -> #DIV/0! | H21: =G21/D21 -> #DIV/0! | J21: =I21/D21 -> #DIV/0!
D22: =COUNTIFS(花名册!C:C,B22) -> 0 | F22: =E22/D22 -> #DIV/0! | H22: =G22/D22 -> #DIV/0! | J22: =I22/D22 -> #DIV/0!
B23: 代维合计 | D23: =D22 -> 0 | E23: =E22 -> 0 | F23: =E23/D23 -> #DIV/0! | G23: =G22 -> 0 | H23: =G23/D23 -> #DIV/0! | I23: =I22 -> 0 | J23: =I23/D23 -> #DIV/0!
B24: 贵州工程 | D24: =COUNTIFS(花名册!C:C,B24) -> 0 | F24: =E24/D24 -> #DIV/0! | H24: =G24/D24 -> #DIV/0! | J24: =I24/D24 -> #DIV/0!
A25: 浙江 | D25: =COUNTIFS(花名册!C:C,B25) -> 0 | F25: =E25/D25 -> #DIV/0! | H25: =G25/D25 -> #DIV/0! | J25: =I25/D25 -> #DIV/0!
D26: =COUNTIFS(花名册!C:C,B26) -> 0 | F26: =E26/D26 -> #DIV/0! | H26: =G26/D26 -> #DIV/0! | J26: =I26/D26 -> #DIV/0!
D27: =COUNTIFS(花名册!C:C,B27) -> 0 | F27: =E27/D27 -> #DIV/0! | H27: =G27/D27 -> #DIV/0! | J27: =I27/D27 -> #DIV/0!
D28: =COUNTIFS(花名册!C:C,B28) -> 0 | F28: =E28/D28 -> #DIV/0! | H28: =G28/D28 -> #DIV/0! | J28: =I28/D28 -> #DIV/0!
D29: =COUNTIFS(花名册!C:C,B29) -> 0 | F29: =E29/D29 -> #DIV/0! | H29: =G29/D29 -> #DIV/0! | J29: =I29/(D29-1) -> 0
B30: 代维合计 | D30: =SUM(D26:D29) -> 0 | E30: =SUM(E26:E29) -> 0 | F30: =E30/D30 -> #DIV/0! | G30: =SUM(G26:G29) -> 0 | H30: =G30/D30 -> #DIV/0! | I30: =SUM(I26:I29) -> 0 | J30: =I30/D30 -> #DIV/0!
B31: 浙江工程 | D31: =COUNTIFS(花名册!C:C,B31)+COUNTIFS(花名册!C:C,"舟山工程")+COUNTIFS(花名册!C:C,"温州工程")+COUNTIFS(花名册!C:C,"衢州工程")+COUNTIFS(花名册!C:C,"台州工程") -> 1 | F31: =E31/D31 -> 0 | H31: =G31/D31 -> 0 | J31: =I31/D31 -> 0
A32: 四川 | D32: =COUNTIFS(花名册!C:C,B32) -> 0 | F32: =E32/D32 -> #DIV/0! | H32: =G32/D32 -> #DIV/0! | J32: =I32/D32 -> #DIV/0!
D33: =COUNTIFS(花名册!C:C,B33) -> 0 | F33: =E33/D33 -> #DIV/0! | H33: =G33/D33 -> #DIV/0! | J33: =I33/D33 -> #DIV/0!
D34: =COUNTIFS(花名册!C:C,B34) -> 0 | F34: =E34/D34 -> #DIV/0! | H34: =G34/D34 -> #DIV/0! | J34: =I34/D34 -> #DIV/0!
D35: =COUNTIFS(花名册!C:C,B35) -> 0 | F35: =E35/D35 -> #DIV/0! | H35: =G35/D35 -> #DIV/0! | J35: =I35/D35 -> #DIV/0!
B36: 代维合计 | D36: =SUM(D33:D35) -> 0 | E36: =SUM(E33:E35) -> 0 | F36: =E36/D36 -> #DIV/0! | G36: =SUM(G33:G35) -> 0 | H36: =G36/D36 -> #DIV/0! | I36: =SUM(I33:I35) -> 0 | J36: =I36/D36 -> #DIV/0!
B37: 四川工程 | D37: =COUNTIFS(花名册!C:C,B37) -> 0 | F37: =E37/D37 -> #DIV/0! | H37: =G37/D37 -> #DIV/0! | J37: =I37/(D37-1) -> 0
A38: 陕西 | D38: =COUNTIFS(花名册!C:C,B38) -> 0 | F38: =E38/D38 -> #DIV/0! | H38: =G38/D38 -> #DIV/0! | J38: =I38/D38 -> #DIV/0!
D39: =COUNTIFS(花名册!C:C,B39) -> 0 | F39: =E39/D39 -> #DIV/0! | H39: =G39/D39 -> #DIV/0! | J39: =I39/D39 -> #DIV/0!
D40: =COUNTIFS(花名册!C:C,B40) -> 0 | F40: =E40/D40 -> #DIV/0! | H40: =G40/D40 -> #DIV/0! | J40: =I40/D40 -> #DIV/0!
...

Sheet 花名册
A1: 2026年4月人员花名册
A2: 46113
A3: 序号 | B3: 部门 | C3: 部门/项目 | D3: 姓名 | E3: 身份证号码 | F3: 出生日期 | G3: 年龄 | H3: 性别 | I3: 岗位 | J3: 人员分类 | K3: 所属专业 | L3: 联系方式 | M3: 入职公司 | N3: 学历 | O3: 毕业院校 | P3: 专业 | Q3: 入职时间 | R3: 电工证 | S3: 登高证 | T3: 焊工证 | U3: 安全员 (通管局） | V3: 安全员 （建设厅） | W3: 一级建造师 | X3: 二级建造师
A4: 1 | B4: 总部 | C4: 公司领导
A5: 2 | B5: 总部 | C5: 公司领导
A6: 3 | B6: 总部 | C6: 公司领导
A7: 4 | B7: 总部 | C7: 公司领导
A8: 5 | B8: 总部 | C8: 技术中心
A9: 6 | B9: 总部 | C9: 技术中心
A10: 7 | B10: 总部 | C10: 办公室
A11: 8 | B11: 总部 | C11: 办公室
A12: 9 | B12: 总部 | C12: 办公室
A13: 22 | B13: 总部 | C13: 人力资源部
A14: 23 | B14: 总部 | C14: 人力资源部
A15: 24 | B15: 总部 | C15: 人力资源部
... A89: 98 | B89: 运营商事业部 | C89: 九江
